[2025-05-01T01:47:54.741+0000] {taskinstance.py:1979} INFO - Dependencies all met for dep_context=non-requeueable deps ti=<TaskInstance: bikeshare_etl_pipeline.download_zipfile_to_bucket manual__2025-05-01T01:46:43.322227+00:00 [queued]>
[2025-05-01T01:47:54.749+0000] {taskinstance.py:1979} INFO - Dependencies all met for dep_context=requeueable deps ti=<TaskInstance: bikeshare_etl_pipeline.download_zipfile_to_bucket manual__2025-05-01T01:46:43.322227+00:00 [queued]>
[2025-05-01T01:47:54.750+0000] {taskinstance.py:2193} INFO - Starting attempt 2 of 2
[2025-05-01T01:47:54.764+0000] {taskinstance.py:2217} INFO - Executing <Task(_PythonDecoratedOperator): download_zipfile_to_bucket> on 2025-05-01 01:46:43.322227+00:00
[2025-05-01T01:47:54.771+0000] {standard_task_runner.py:60} INFO - Started process 1156 to run task
[2025-05-01T01:47:54.775+0000] {standard_task_runner.py:87} INFO - Running: ['airflow', 'tasks', 'run', 'bikeshare_etl_pipeline', 'download_zipfile_to_bucket', 'manual__2025-05-01T01:46:43.322227+00:00', '--job-id', '213', '--raw', '--subdir', 'DAGS_FOLDER/etl_pipeline.py', '--cfg-path', '/tmp/tmp6lon6d3e']
[2025-05-01T01:47:54.778+0000] {standard_task_runner.py:88} INFO - Job 213: Subtask download_zipfile_to_bucket
[2025-05-01T01:47:54.973+0000] {task_command.py:423} INFO - Running <TaskInstance: bikeshare_etl_pipeline.download_zipfile_to_bucket manual__2025-05-01T01:46:43.322227+00:00 [running]> on host 480ba1d570eb
[2025-05-01T01:47:55.238+0000] {taskinstance.py:2513} INFO - Exporting env vars: AIRFLOW_CTX_DAG_EMAIL='adedoyinsamuel25@gmail.com' AIRFLOW_CTX_DAG_OWNER='airflow' AIRFLOW_CTX_DAG_ID='bikeshare_etl_pipeline' AIRFLOW_CTX_TASK_ID='download_zipfile_to_bucket' AIRFLOW_CTX_EXECUTION_DATE='2025-05-01T01:46:43.322227+00:00' AIRFLOW_CTX_TRY_NUMBER='2' AIRFLOW_CTX_DAG_RUN_ID='manual__2025-05-01T01:46:43.322227+00:00'
[2025-05-01T01:48:01.048+0000] {base.py:83} INFO - Using connection ID 'minio_s3_conn' for task execution.
[2025-05-01T01:48:01.084+0000] {base.py:83} INFO - Using connection ID 'minio_s3_conn' for task execution.
[2025-05-01T01:48:01.085+0000] {connection_wrapper.py:387} INFO - AWS Connection (conn_id='minio_s3_conn', conn_type='aws') credentials retrieved from extra.
[2025-05-01T01:48:01.414+0000] {taskinstance.py:2731} ERROR - Task failed with exception
Traceback (most recent call last):
  File "/home/airflow/.local/lib/python3.8/site-packages/airflow/models/taskinstance.py", line 444, in _execute_task
    result = _execute_callable(context=context, **execute_callable_kwargs)
  File "/home/airflow/.local/lib/python3.8/site-packages/airflow/models/taskinstance.py", line 414, in _execute_callable
    return execute_callable(context=context, **execute_callable_kwargs)
  File "/home/airflow/.local/lib/python3.8/site-packages/airflow/decorators/base.py", line 241, in execute
    return_value = super().execute(context)
  File "/home/airflow/.local/lib/python3.8/site-packages/airflow/operators/python.py", line 200, in execute
    return_value = self.execute_callable()
  File "/home/airflow/.local/lib/python3.8/site-packages/airflow/operators/python.py", line 217, in execute_callable
    return self.python_callable(*self.op_args, **self.op_kwargs)
  File "/opt/airflow/dags/etl_pipeline.py", line 65, in download_zipfile_to_bucket
    s3_hook.load_bytes(
  File "/home/airflow/.local/lib/python3.8/site-packages/airflow/providers/amazon/aws/hooks/s3.py", line 137, in wrapper
    return func(*bound_args.args, **bound_args.kwargs)
  File "/home/airflow/.local/lib/python3.8/site-packages/airflow/providers/amazon/aws/hooks/s3.py", line 91, in wrapper
    return func(*bound_args.args, **bound_args.kwargs)
  File "/home/airflow/.local/lib/python3.8/site-packages/airflow/providers/amazon/aws/hooks/s3.py", line 1188, in load_bytes
    self._upload_file_obj(f, key, bucket_name, replace, encrypt, acl_policy)
  File "/home/airflow/.local/lib/python3.8/site-packages/airflow/providers/amazon/aws/hooks/s3.py", line 1238, in _upload_file_obj
    client.upload_fileobj(
  File "/home/airflow/.local/lib/python3.8/site-packages/boto3/s3/inject.py", line 642, in upload_fileobj
    return future.result()
  File "/home/airflow/.local/lib/python3.8/site-packages/s3transfer/futures.py", line 103, in result
    return self._coordinator.result()
  File "/home/airflow/.local/lib/python3.8/site-packages/s3transfer/futures.py", line 266, in result
    raise self._exception
  File "/home/airflow/.local/lib/python3.8/site-packages/s3transfer/tasks.py", line 139, in __call__
    return self._execute_main(kwargs)
  File "/home/airflow/.local/lib/python3.8/site-packages/s3transfer/tasks.py", line 162, in _execute_main
    return_value = self._main(**kwargs)
  File "/home/airflow/.local/lib/python3.8/site-packages/s3transfer/upload.py", line 764, in _main
    client.put_object(Bucket=bucket, Key=key, Body=body, **extra_args)
  File "/home/airflow/.local/lib/python3.8/site-packages/botocore/client.py", line 553, in _api_call
    return self._make_api_call(operation_name, kwargs)
  File "/home/airflow/.local/lib/python3.8/site-packages/botocore/client.py", line 1009, in _make_api_call
    raise error_class(parsed_response, operation_name)
botocore.exceptions.ClientError: An error occurred (InvalidAccessKeyId) when calling the PutObject operation: The Access Key Id you provided does not exist in our records.
[2025-05-01T01:48:01.459+0000] {taskinstance.py:1149} INFO - Marking task as FAILED. dag_id=bikeshare_etl_pipeline, task_id=download_zipfile_to_bucket, execution_date=20250501T014643, start_date=20250501T014754, end_date=20250501T014801
[2025-05-01T01:48:01.498+0000] {standard_task_runner.py:107} ERROR - Failed to execute job 213 for task download_zipfile_to_bucket (An error occurred (InvalidAccessKeyId) when calling the PutObject operation: The Access Key Id you provided does not exist in our records.; 1156)
[2025-05-01T01:48:01.537+0000] {local_task_job_runner.py:234} INFO - Task exited with return code 1
[2025-05-01T01:48:01.641+0000] {taskinstance.py:3312} INFO - 0 downstream tasks scheduled from follow-on schedule check
