[2025-04-30T23:35:06.619+0000] {taskinstance.py:1979} INFO - Dependencies all met for dep_context=non-requeueable deps ti=<TaskInstance: bikeshare_etl_pipeline.transform_data manual__2025-04-30T23:04:13.923792+00:00 [queued]>
[2025-04-30T23:35:06.630+0000] {taskinstance.py:1979} INFO - Dependencies all met for dep_context=requeueable deps ti=<TaskInstance: bikeshare_etl_pipeline.transform_data manual__2025-04-30T23:04:13.923792+00:00 [queued]>
[2025-04-30T23:35:06.633+0000] {taskinstance.py:2193} INFO - Starting attempt 4 of 4
[2025-04-30T23:35:06.657+0000] {taskinstance.py:2217} INFO - Executing <Task(_PythonDecoratedOperator): transform_data> on 2025-04-30 23:04:13.923792+00:00
[2025-04-30T23:35:06.662+0000] {standard_task_runner.py:60} INFO - Started process 16656 to run task
[2025-04-30T23:35:06.667+0000] {standard_task_runner.py:87} INFO - Running: ['airflow', 'tasks', 'run', 'bikeshare_etl_pipeline', 'transform_data', 'manual__2025-04-30T23:04:13.923792+00:00', '--job-id', '140', '--raw', '--subdir', 'DAGS_FOLDER/etl_pipeline.py', '--cfg-path', '/tmp/tmp2gj1p_ge']
[2025-04-30T23:35:06.670+0000] {standard_task_runner.py:88} INFO - Job 140: Subtask transform_data
[2025-04-30T23:35:06.898+0000] {task_command.py:423} INFO - Running <TaskInstance: bikeshare_etl_pipeline.transform_data manual__2025-04-30T23:04:13.923792+00:00 [running]> on host e4f2445a264f
[2025-04-30T23:35:07.230+0000] {taskinstance.py:2513} INFO - Exporting env vars: AIRFLOW_CTX_DAG_EMAIL='adedoyinsamuel25@gmail.com' AIRFLOW_CTX_DAG_OWNER='airflow' AIRFLOW_CTX_DAG_ID='bikeshare_etl_pipeline' AIRFLOW_CTX_TASK_ID='transform_data' AIRFLOW_CTX_EXECUTION_DATE='2025-04-30T23:04:13.923792+00:00' AIRFLOW_CTX_TRY_NUMBER='4' AIRFLOW_CTX_DAG_RUN_ID='manual__2025-04-30T23:04:13.923792+00:00'
[2025-04-30T23:35:09.570+0000] {base.py:83} INFO - Using connection ID 'minio_s3_conn' for task execution.
[2025-04-30T23:35:09.575+0000] {connection_wrapper.py:387} INFO - AWS Connection (conn_id='minio_s3_conn', conn_type='aws') credentials retrieved from extra.
[2025-04-30T23:35:11.180+0000] {taskinstance.py:2731} ERROR - Task failed with exception
Traceback (most recent call last):
  File "/home/airflow/.local/lib/python3.8/site-packages/boto3/s3/transfer.py", line 371, in upload_file
    future.result()
  File "/home/airflow/.local/lib/python3.8/site-packages/s3transfer/futures.py", line 103, in result
    return self._coordinator.result()
  File "/home/airflow/.local/lib/python3.8/site-packages/s3transfer/futures.py", line 266, in result
    raise self._exception
  File "/home/airflow/.local/lib/python3.8/site-packages/s3transfer/tasks.py", line 139, in __call__
    return self._execute_main(kwargs)
  File "/home/airflow/.local/lib/python3.8/site-packages/s3transfer/tasks.py", line 162, in _execute_main
    return_value = self._main(**kwargs)
  File "/home/airflow/.local/lib/python3.8/site-packages/s3transfer/upload.py", line 764, in _main
    client.put_object(Bucket=bucket, Key=key, Body=body, **extra_args)
  File "/home/airflow/.local/lib/python3.8/site-packages/botocore/client.py", line 553, in _api_call
    return self._make_api_call(operation_name, kwargs)
  File "/home/airflow/.local/lib/python3.8/site-packages/botocore/client.py", line 1009, in _make_api_call
    raise error_class(parsed_response, operation_name)
botocore.exceptions.ClientError: An error occurred (InvalidBucketName) when calling the PutObject operation: The specified bucket is not valid.

During handling of the above exception, another exception occurred:

Traceback (most recent call last):
  File "/home/airflow/.local/lib/python3.8/site-packages/airflow/models/taskinstance.py", line 444, in _execute_task
    result = _execute_callable(context=context, **execute_callable_kwargs)
  File "/home/airflow/.local/lib/python3.8/site-packages/airflow/models/taskinstance.py", line 414, in _execute_callable
    return execute_callable(context=context, **execute_callable_kwargs)
  File "/home/airflow/.local/lib/python3.8/site-packages/airflow/decorators/base.py", line 241, in execute
    return_value = super().execute(context)
  File "/home/airflow/.local/lib/python3.8/site-packages/airflow/operators/python.py", line 200, in execute
    return_value = self.execute_callable()
  File "/home/airflow/.local/lib/python3.8/site-packages/airflow/operators/python.py", line 217, in execute_callable
    return self.python_callable(*self.op_args, **self.op_kwargs)
  File "/opt/airflow/dags/etl_pipeline.py", line 156, in transform_data
    s3_hook.load_file(
  File "/home/airflow/.local/lib/python3.8/site-packages/airflow/providers/amazon/aws/hooks/s3.py", line 137, in wrapper
    return func(*bound_args.args, **bound_args.kwargs)
  File "/home/airflow/.local/lib/python3.8/site-packages/airflow/providers/amazon/aws/hooks/s3.py", line 91, in wrapper
    return func(*bound_args.args, **bound_args.kwargs)
  File "/home/airflow/.local/lib/python3.8/site-packages/airflow/providers/amazon/aws/hooks/s3.py", line 1104, in load_file
    client.upload_file(filename, bucket_name, key, ExtraArgs=extra_args, Config=self.transfer_config)
  File "/home/airflow/.local/lib/python3.8/site-packages/boto3/s3/inject.py", line 145, in upload_file
    return transfer.upload_file(
  File "/home/airflow/.local/lib/python3.8/site-packages/boto3/s3/transfer.py", line 377, in upload_file
    raise S3UploadFailedError(
boto3.exceptions.S3UploadFailedError: Failed to upload /opt/airflow/dags/data/30-04-2025_capitalbikeshare-tripdata.parquet to MINIO_BUCKET_CLEANED/30-04-2025/capitalbikeshare-tripdata.parquet: An error occurred (InvalidBucketName) when calling the PutObject operation: The specified bucket is not valid.
[2025-04-30T23:35:11.247+0000] {taskinstance.py:1149} INFO - Marking task as FAILED. dag_id=bikeshare_etl_pipeline, task_id=transform_data, execution_date=20250430T230413, start_date=20250430T233506, end_date=20250430T233511
[2025-04-30T23:35:11.288+0000] {standard_task_runner.py:107} ERROR - Failed to execute job 140 for task transform_data (Failed to upload /opt/airflow/dags/data/30-04-2025_capitalbikeshare-tripdata.parquet to MINIO_BUCKET_CLEANED/30-04-2025/capitalbikeshare-tripdata.parquet: An error occurred (InvalidBucketName) when calling the PutObject operation: The specified bucket is not valid.; 16656)
[2025-04-30T23:35:11.336+0000] {local_task_job_runner.py:234} INFO - Task exited with return code 1
[2025-04-30T23:35:11.407+0000] {taskinstance.py:3312} INFO - 0 downstream tasks scheduled from follow-on schedule check
