[2025-04-30T23:29:55.928+0000] {taskinstance.py:1979} INFO - Dependencies all met for dep_context=non-requeueable deps ti=<TaskInstance: bikeshare_etl_pipeline.transform_data manual__2025-04-30T22:38:47.303758+00:00 [queued]>
[2025-04-30T23:29:55.939+0000] {taskinstance.py:1979} INFO - Dependencies all met for dep_context=requeueable deps ti=<TaskInstance: bikeshare_etl_pipeline.transform_data manual__2025-04-30T22:38:47.303758+00:00 [queued]>
[2025-04-30T23:29:55.939+0000] {taskinstance.py:2193} INFO - Starting attempt 10 of 11
[2025-04-30T23:29:55.953+0000] {taskinstance.py:2217} INFO - Executing <Task(_PythonDecoratedOperator): transform_data> on 2025-04-30 22:38:47.303758+00:00
[2025-04-30T23:29:55.958+0000] {standard_task_runner.py:60} INFO - Started process 16127 to run task
[2025-04-30T23:29:55.961+0000] {standard_task_runner.py:87} INFO - Running: ['airflow', 'tasks', 'run', 'bikeshare_etl_pipeline', 'transform_data', 'manual__2025-04-30T22:38:47.303758+00:00', '--job-id', '137', '--raw', '--subdir', 'DAGS_FOLDER/etl_pipeline.py', '--cfg-path', '/tmp/tmpzongrewy']
[2025-04-30T23:29:55.963+0000] {standard_task_runner.py:88} INFO - Job 137: Subtask transform_data
[2025-04-30T23:29:56.064+0000] {task_command.py:423} INFO - Running <TaskInstance: bikeshare_etl_pipeline.transform_data manual__2025-04-30T22:38:47.303758+00:00 [running]> on host e4f2445a264f
[2025-04-30T23:29:56.289+0000] {taskinstance.py:2513} INFO - Exporting env vars: AIRFLOW_CTX_DAG_EMAIL='adedoyinsamuel25@gmail.com' AIRFLOW_CTX_DAG_OWNER='airflow' AIRFLOW_CTX_DAG_ID='bikeshare_etl_pipeline' AIRFLOW_CTX_TASK_ID='transform_data' AIRFLOW_CTX_EXECUTION_DATE='2025-04-30T22:38:47.303758+00:00' AIRFLOW_CTX_TRY_NUMBER='10' AIRFLOW_CTX_DAG_RUN_ID='manual__2025-04-30T22:38:47.303758+00:00'
[2025-04-30T23:29:58.580+0000] {base.py:83} INFO - Using connection ID 'minio_s3_conn' for task execution.
[2025-04-30T23:29:58.582+0000] {connection_wrapper.py:387} INFO - AWS Connection (conn_id='minio_s3_conn', conn_type='aws') credentials retrieved from extra.
[2025-04-30T23:30:01.715+0000] {taskinstance.py:2731} ERROR - Task failed with exception
Traceback (most recent call last):
  File "/home/airflow/.local/lib/python3.8/site-packages/airflow/models/taskinstance.py", line 444, in _execute_task
    result = _execute_callable(context=context, **execute_callable_kwargs)
  File "/home/airflow/.local/lib/python3.8/site-packages/airflow/models/taskinstance.py", line 414, in _execute_callable
    return execute_callable(context=context, **execute_callable_kwargs)
  File "/home/airflow/.local/lib/python3.8/site-packages/airflow/decorators/base.py", line 241, in execute
    return_value = super().execute(context)
  File "/home/airflow/.local/lib/python3.8/site-packages/airflow/operators/python.py", line 200, in execute
    return_value = self.execute_callable()
  File "/home/airflow/.local/lib/python3.8/site-packages/airflow/operators/python.py", line 217, in execute_callable
    return self.python_callable(*self.op_args, **self.op_kwargs)
  File "/opt/airflow/dags/etl_pipeline.py", line 154, in transform_data
    s3_hook.load_file(
  File "/home/airflow/.local/lib/python3.8/site-packages/airflow/providers/amazon/aws/hooks/s3.py", line 137, in wrapper
    return func(*bound_args.args, **bound_args.kwargs)
  File "/home/airflow/.local/lib/python3.8/site-packages/airflow/providers/amazon/aws/hooks/s3.py", line 91, in wrapper
    return func(*bound_args.args, **bound_args.kwargs)
  File "/home/airflow/.local/lib/python3.8/site-packages/airflow/providers/amazon/aws/hooks/s3.py", line 1104, in load_file
    client.upload_file(filename, bucket_name, key, ExtraArgs=extra_args, Config=self.transfer_config)
  File "/home/airflow/.local/lib/python3.8/site-packages/boto3/s3/inject.py", line 145, in upload_file
    return transfer.upload_file(
  File "/home/airflow/.local/lib/python3.8/site-packages/boto3/s3/transfer.py", line 371, in upload_file
    future.result()
  File "/home/airflow/.local/lib/python3.8/site-packages/s3transfer/futures.py", line 103, in result
    return self._coordinator.result()
  File "/home/airflow/.local/lib/python3.8/site-packages/s3transfer/futures.py", line 266, in result
    raise self._exception
  File "/home/airflow/.local/lib/python3.8/site-packages/s3transfer/tasks.py", line 269, in _main
    self._submit(transfer_future=transfer_future, **kwargs)
  File "/home/airflow/.local/lib/python3.8/site-packages/s3transfer/upload.py", line 591, in _submit
    upload_input_manager.provide_transfer_size(transfer_future)
  File "/home/airflow/.local/lib/python3.8/site-packages/s3transfer/upload.py", line 244, in provide_transfer_size
    self._osutil.get_file_size(transfer_future.meta.call_args.fileobj)
  File "/home/airflow/.local/lib/python3.8/site-packages/s3transfer/utils.py", line 251, in get_file_size
    return os.path.getsize(filename)
  File "/usr/local/lib/python3.8/genericpath.py", line 50, in getsize
    return os.stat(filename).st_size
FileNotFoundError: [Errno 2] No such file or directory: 'None'
[2025-04-30T23:30:01.817+0000] {taskinstance.py:1149} INFO - Marking task as UP_FOR_RETRY. dag_id=bikeshare_etl_pipeline, task_id=transform_data, execution_date=20250430T223847, start_date=20250430T232955, end_date=20250430T233001
[2025-04-30T23:30:01.853+0000] {standard_task_runner.py:107} ERROR - Failed to execute job 137 for task transform_data ([Errno 2] No such file or directory: 'None'; 16127)
[2025-04-30T23:30:01.887+0000] {local_task_job_runner.py:234} INFO - Task exited with return code 1
[2025-04-30T23:30:01.993+0000] {taskinstance.py:3312} INFO - 0 downstream tasks scheduled from follow-on schedule check
